Workbook

Sheet גיליון2
A1: name | B1: מקט/PROD ID | C1: MATCH
A2: Samsung 85'' QLED Q6F 4K Smart TV (2025) | B2: S-102666 | C2: [id=52191; name=1; url=/media/ptvj3lp4/1.png], [id=52192; name=2; url=/media/32olzvf0/2.png], [id=52193; name=3; url=/media/r1qbvyok/3.png], [id=52194; name=4; url=/media/rmoprlbt/4.png], [id=52195; name=5; url=/media/xwfbdmjr/5.png], [id=52175; name=7; url=/media/ojjamkts/7.png]
A3: S-102666 | B3: S-102666 | C3: [id=52191; name=1; url=/media/ptvj3lp4/1.png], [id=52192; name=2; url=/media/32olzvf0/2.png], [id=52193; name=3; url=/media/r1qbvyok/3.png], [id=52194; name=4; url=/media/rmoprlbt/4.png], [id=52195; name=5; url=/media/xwfbdmjr/5.png], [id=52175; name=7; url=/media/ojjamkts/7.png]
A4: Apple iPad Air 13 M4 Wi-Fi 256GB - טאבלט | B4: 1-DCLG74FR | C4: [id=53585; name=Ipad Air 13 Inch M4 Chip Wi Fi Starlight 2 Up Print USEN; url=/media/ggwoaayo/ipad_air_13-inch_m4_chip_wi-fi_starlight_2-up_print__usen.jpg]
A5: Starlight | B5: S-103675 | C5: [id=53585; name=Ipad Air 13 Inch M4 Chip Wi Fi Starlight 2 Up Print USEN; url=/media/ggwoaayo/ipad_air_13-inch_m4_chip_wi-fi_starlight_2-up_print__usen.jpg]
A6: Space Grey | B6: S-103674 | C6: id=53587; name=Ipad Air 13 Inch M4 Chip Wi Fi Space Gray 2 Up Print USEN; url=/media/ofmjmpvi/ipad_air_13-inch_m4_chip_wi-fi_space_gray_2-up_print__usen.jpg
A7: Xiaomi 17 5G 12GB+512GB בצבע שחור | B7: S-102440 | C7: [id=53806; name=Xiaomi 17 Black 1; url=/media/cc/xiaomi-17-black-1.jpg], [id=53807; name=Xiaomi 17 Black 2; url=/media/fjdojiyv/xiaomi-17-black-2.jpg], [id=53808; name=Xiaomi 17 Black 3; url=/media/nlqpthkz/xiaomi-17-black-3.jpg], [id=53809; name=Xiaomi 17 Black 4; url=/media/en0p4p2d/xiaomi-17-black-4.jpg]
A8: Samsung QLED Q7F 75" 4K Vision AI Smart TV 2025 | B8: 1-DB3AGAXC | C8: [id=52227; name=1; url=/media/u0hf2gw4/1.png], [id=52228; name=2; url=/media/4kamsxkc/2.png], [id=52229; name=3; url=/media/adeplfi3/3.png], [id=52230; name=4; url=/media/ogfb12ac/4.png], [id=52175; name=7; url=/media/ojjamkts/7.png]
A9: S-102674 | B9: S-102674 | C9: [id=52227; name=1; url=/media/u0hf2gw4/1.png], [id=52228; name=2; url=/media/4kamsxkc/2.png], [id=52229; name=3; url=/media/adeplfi3/3.png], [id=52230; name=4; url=/media/ogfb12ac/4.png], [id=52175; name=7; url=/media/ojjamkts/7.png]
A10: Xiaomi 17 Ultra 5G 12GB+512GB בצבע שחור | B10: S-104011 | C10: [id=53825; name=Xiaomi 17 Ultra Black 1; url=/media/ilvjiesy/xiaomi-17-ultra-black-1.jpg], [id=53826; name=Xiaomi 17 Ultra Black 2; url=/media/ntmjkzwn/xiaomi-17-ultra-black-2.jpg], [id=53827; name=Xiaomi 17 Ultra Black 3; url=/media/vkumexxu/xiaomi-17-ultra-black-3.jpg], [id=53828; name=Xiaomi 17 Ultra Black 4; url=/media/zivk4kou/xiaomi-17-ultra-black-4.jpg]
A11: Samsung Galaxy A57 5G 128GB | B11: 1-DCTXMS8O | C11: [id=53932; name=SM A576 Galaxya57 5G Front Awesomeicyblue; url=/media/psmldjtd/sm-a576_galaxya57_5g_front_awesomeicyblue.jpg], [id=53933; name=SM A576 Galaxya57 5G Front2 Awesomeicyblue; url=/media/glbpfzfx/sm-a576_galaxya57_5g_front2_awesomeicyblue.jpg], [id=53934; name=SM A576 Galaxya57 5G Frontl30 Awesomeicyblue; url=/media/hnval03r/sm-a576_galaxya57_5g_frontl30_awesomeicyblue.jpg], [id=53935; name=SM A576 Galaxya57 5G Frontr30 Awesomeicyblue; url=/media/smtbkp3v/sm-a576_galaxya57_5g_frontr30_awesomeicyblue.jpg], [id=53929; name=SM A576 Galaxya57 5G Back Awesomeicyblue; url=/media/kjdjul0i/sm-a576_galaxya57_5g_back_awesomeicyblue.jpg], [id=53930; name=SM A576 Galaxya57 5G Backl30 Awesomeicyblue; url=/media/ubxi21qq/sm-a576_galaxya57_5g_backl30_awesomeicyblue.jpg], [id=53931; name=SM A576 Galaxya57 5G Backr30 Awesomeicyblue; url=/media/nlld0a3o/sm-a576_galaxya57_5g_backr30_awesomeicyblue.jpg]
A12: S-103447 | B12: S-103447 | C12: id=53938; name=SM A576 Galaxya57 5G Front Awesomeicyblue (1); url=/media/0gsmlyti/sm-a576_galaxya57_5g_front_awesomeicyblue.jpg
... A2098: iPad 11 | B2098: S-98513 | C2098: [id=46751; name=1; url=/media/swcfjjrr/1.png]

Sheet גיליון3
A1: sku | B1: תמונה | C1: מלאי
A2: S-104345 | B2: =VLOOKUP(A2,גיליון2!B:C,2,FALSE) -> #N/A | C2: =VLOOKUP(A2,[2]גיליון1!$B:$D,3,FALSE) -> #N/A
A3: S-104346 | B3: =VLOOKUP(A3,גיליון2!B:C,2,FALSE) -> #N/A | C3: =VLOOKUP(A3,[2]גיליון1!$B:$D,3,FALSE) -> #N/A
A4: S-104344 | B4: =VLOOKUP(A4,גיליון2!B:C,2,FALSE) -> #N/A | C4: =VLOOKUP(A4,[2]גיליון1!$B:$D,3,FALSE) -> #N/A
A5: S-104343 | B5: =VLOOKUP(A5,גיליון2!B:C,2,FALSE) -> #N/A | C5: =VLOOKUP(A5,[2]גיליון1!$B:$D,3,FALSE) -> #N/A
A6: S-104342 | B6: =VLOOKUP(A6,גיליון2!B:C,2,FALSE) -> #N/A | C6: =VLOOKUP(A6,[2]גיליון1!$B:$D,3,FALSE) -> 18 | D6: =VLOOKUP(A6,[2]גיליון1!$B:$D,2,FALSE) -> Sony PS5 Dualsense Pearl | E6: 2
A7: S-104352 | B7: =VLOOKUP(A7,גיליון2!B:C,2,FALSE) -> #N/A | C7: =VLOOKUP(A7,[2]גיליון1!$B:$D,3,FALSE) -> 10 | D7: =VLOOKUP(A7,[2]גיליון1!$B:$D,2,FALSE) -> Sony PS5 Dualsense 007 First Light LE
A8: S-104368 | B8: =VLOOKUP(A8,גיליון2!B:C,2,FALSE) -> #N/A | C8: =VLOOKUP(A8,[2]גיליון1!$B:$D,3,FALSE) -> #N/A
A9: S-104340 | B9: =VLOOKUP(A9,גיליון2!B:C,2,FALSE) -> #N/A | C9: =VLOOKUP(A9,[2]גיליון1!$B:$D,3,FALSE) -> 19 | D9: =VLOOKUP(A9,[2]גיליון1!$B:$D,2,FALSE) -> Sony PS5 DualSense Teal
A10: S-104341 | B10: =VLOOKUP(A10,גיליון2!B:C,2,FALSE) -> #N/A | C10: =VLOOKUP(A10,[2]גיליון1!$B:$D,3,FALSE) -> 20 | D10: =VLOOKUP(A10,[2]גיליון1!$B:$D,2,FALSE) -> Sony PS5 Dualsense Indigo
A11: S-104367 | B11: =VLOOKUP(A11,גיליון2!B:C,2,FALSE) -> #N/A | C11: =VLOOKUP(A11,[2]גיליון1!$B:$D,3,FALSE) -> #N/A
A12: S-104369 | B12: =VLOOKUP(A12,גיליון2!B:C,2,FALSE) -> #N/A | C12: =VLOOKUP(A12,[2]גיליון1!$B:$D,3,FALSE) -> #N/A
A13: S-104366 | B13: =VLOOKUP(A13,גיליון2!B:C,2,FALSE) -> #N/A | C13: =VLOOKUP(A13,[2]גיליון1!$B:$D,3,FALSE) -> #N/A
A14: S-104365 | B14: =VLOOKUP(A14,גיליון2!B:C,2,FALSE) -> #N/A | C14: =VLOOKUP(A14,[2]גיליון1!$B:$D,3,FALSE) -> #N/A
A15: S-104364 | B15: =VLOOKUP(A15,גיליון2!B:C,2,FALSE) -> #N/A | C15: =VLOOKUP(A15,[2]גיליון1!$B:$D,3,FALSE) -> #N/A
A16: S-104362 | B16: =VLOOKUP(A16,גיליון2!B:C,2,FALSE) -> #N/A | C16: =VLOOKUP(A16,[2]גיליון1!$B:$D,3,FALSE) -> #N/A
A17: S-104363 | B17: =VLOOKUP(A17,גיליון2!B:C,2,FALSE) -> #N/A | C17: =VLOOKUP(A17,[2]גיליון1!$B:$D,3,FALSE) -> #N/A
A18: S-104361 | B18: =VLOOKUP(A18,גיליון2!B:C,2,FALSE) -> #N/A | C18: =VLOOKUP(A18,[2]גיליון1!$B:$D,3,FALSE) -> #N/A
A19: S-104358 | B19: =VLOOKUP(A19,גיליון2!B:C,2,FALSE) -> #N/A | C19: =VLOOKUP(A19,[2]גיליון1!$B:$D,3,FALSE) -> #N/A
A20: S-104360 | B20: =VLOOKUP(A20,גיליון2!B:C,2,FALSE) -> #N/A | C20: =VLOOKUP(A20,[2]גיליון1!$B:$D,3,FALSE) -> #N/A
A21: S-104359 | B21: =VLOOKUP(A21,גיליון2!B:C,2,FALSE) -> #N/A | C21: =VLOOKUP(A21,[2]גיליון1!$B:$D,3,FALSE) -> #N/A
A22: S-104357 | B22: =VLOOKUP(A22,גיליון2!B:C,2,FALSE) -> #N/A | C22: =VLOOKUP(A22,[2]גיליון1!$B:$D,3,FALSE) -> #N/A
... A25: S-103642 | B25: =VLOOKUP(A25,גיליון2!B:C,2,FALSE) -> #N/A | C25: =VLOOKUP(A25,[2]גיליון1!$B:$D,3,FALSE) -> #N/A
A26: S-104065 | B26: =VLOOKUP(A26,גיליון2!B:C,2,FALSE) -> #N/A | C26: =VLOOKUP(A26,[2]גיליון1!$B:$D,3,FALSE) -> 316 | D26: =VLOOKUP(A26,[2]גיליון1!$B:$D,2,FALSE) -> P SP Glass Samsung A57
A27: S-104064 | B27: =VLOOKUP(A27,גיליון2!B:C,2,FALSE) -> #N/A | C27: =VLOOKUP(A27,[2]גיליון1!$B:$D,3,FALSE) -> 92 | D27: =VLOOKUP(A27,[2]גיליון1!$B:$D,2,FALSE) -> P SP Glass Samsung A37
A28: S-104063 | B28: =VLOOKUP(A28,גיליון2!B:C,2,FALSE) -> #N/A | C28: =VLOOKUP(A28,[2]גיליון1!$B:$D,3,FALSE) -> #N/A
A29: S-104062 | B29: =VLOOKUP(A29,גיליון2!B:C,2,FALSE) -> #N/A | C29: =VLOOKUP(A29,[2]גיליון1!$B:$D,3,FALSE) -> #N/A
A30: S-104061 | B30: =VLOOKUP(A30,גיליון2!B:C,2,FALSE) -> #N/A | C30: =VLOOKUP(A30,[2]גיליון1!$B:$D,3,FALSE) -> 1508 | D30: =VLOOKUP(A30,[2]גיליון1!$B:$D,2,FALSE) -> P Samsung A57 Kit 360
A31: S-104058 | B31: =VLOOKUP(A31,גיליון2!B:C,2,FALSE) -> #N/A | C31: =VLOOKUP(A31,[2]גיליון1!$B:$D,3,FALSE) -> 59 | D31: =VLOOKUP(A31,[2]גיליון1!$B:$D,2,FALSE) -> BMX SolidSafe Air Titanium 5K MAGSAFE Power Bank Silver
A32: S-104060 | B32: =VLOOKUP(A32,גיליון2!B:C,2,FALSE) -> #N/A | C32: =VLOOKUP(A32,[2]גיליון1!$B:$D,3,FALSE) -> 621 | D32: =VLOOKUP(A32,[2]גיליון1!$B:$D,2,FALSE) -> P Samsung A37 Kit 360
A33: S-104057 | B33: =VLOOKUP(A33,גיליון2!B:C,2,FALSE) -> #N/A | C33: =VLOOKUP(A33,[2]גיליון1!$B:$D,3,FALSE) -> #N/A
A34: S-104056 | B34: =VLOOKUP(A34,גיליון2!B:C,2,FALSE) -> #N/A | C34: =VLOOKUP(A34,[2]גיליון1!$B:$D,3,FALSE) -> 97 | D34: =VLOOKUP(A34,[2]גיליון1!$B:$D,2,FALSE) -> BMX SolidSafe Air Titanium 5K MAGSAFE Power Bank Black
A35: S-103510 | B35: =VLOOKUP(A35,גיליון2!B:C,2,FALSE) -> #N/A | C35: =VLOOKUP(A35,[2]גיליון1!$B:$D,3,FALSE) -> 1137 | D35: =VLOOKUP(A35,[2]גיליון1!$B:$D,2,FALSE) -> Samsung A57 ORIGINAL Case Clear
A36: S-103511 | B36: =VLOOKUP(A36,גיליון2!B:C,2,FALSE) -> #N/A | C36: =VLOOKUP(A36,[2]גיליון1!$B:$D,3,FALSE) -> 299 | D36: =VLOOKUP(A36,[2]גיליון1!$B:$D,2,FALSE) -> Samsung A37 ORIGINAL Case Clear
A37: S-104288 | B37: =VLOOKUP(A37,גיליון2!B:C,2,FALSE) -> #N/A | C37: =VLOOKUP(A37,[2]גיליון1!$B:$D,3,FALSE) -> 6 | D37: =VLOOKUP(A37,[2]גיליון1!$B:$D,2,FALSE) -> Samsung S24 Ultra 512GB Renewed Mobile Phone Grey TITANIUM
A38: S-104279 | B38: =VLOOKUP(A38,גיליון2!B:C,2,FALSE) -> #N/A | C38: =VLOOKUP(A38,[2]גיליון1!$B:$D,3,FALSE) -> 2 | D38: =VLOOKUP(A38,[2]גיליון1!$B:$D,2,FALSE) -> Samsung S24 FE 256GB Renewed Mobile Phone Grey
A39: S-104283 | B39: =VLOOKUP(A39,גיליון2!B:C,2,FALSE) -> #N/A | C39: =VLOOKUP(A39,[2]גיליון1!$B:$D,3,FALSE) -> 1 | D39: =VLOOKUP(A39,[2]גיליון1!$B:$D,2,FALSE) -> Apple iPhone 15 Pro Max 512GB Renewed Mobile Phone Black Titanium
A40: S-104282 | B40: =VLOOKUP(A40,גיליון2!B:C,2,FALSE) -> #N/A | C40: =VLOOKUP(A40,[2]גיליון1!$B:$D,3,FALSE) -> 3 | D40: =VLOOKUP(A40,[2]גיליון1!$B:$D,2,FALSE) -> Apple iPhone 15 Plus 128GB Renewed Mobile Phone Pink
A41: S-104281 | B41: =VLOOKUP(A41,גיליון2!B:C,2,FALSE) -> #N/A | C41: =VLOOKUP(A41,[2]גיליון1!$B:$D,3,FALSE) -> 2 | D41: =VLOOKUP(A41,[2]גיליון1!$B:$D,2,FALSE) -> Apple iPhone 15 256GB Renewed Mobile Phone Pink
A42: S-104285 | B42: =VLOOKUP(A42,גיליון2!B:C,2,FALSE) -> #N/A | C42: =VLOOKUP(A42,[2]גיליון1!$B:$D,3,FALSE) -> 4 | D42: =VLOOKUP(A42,[2]גיליון1!$B:$D,2,FALSE) -> Apple iPhone 15 128GB Renewed Mobile Phone Pink
...

Sheet גיליון1
B1: name | C1: image | E1: מקט/PROD | F1: imageList
A2: =VLOOKUP(B2,[1]גיליון1!$B:$G,6,FALSE) -> 0 | B2: Samsung 85'' QLED Q6F 4K Smart TV (2025) | E2: =VLOOKUP(A2,[1]גיליון1!$A:$F,6,FALSE) -> #N/A | F2: [id=52191; name=1; url=/media/ptvj3lp4/1.png], [id=52192; name=2; url=/media/32olzvf0/2.png], [id=52193; name=3; url=/media/r1qbvyok/3.png], [id=52194; name=4; url=/media/rmoprlbt/4.png], [id=52195; name=5; url=/media/xwfbdmjr/5.png], [id=52175; name=7; url=/media/ojjamkts/7.png]
A3: =VLOOKUP(B3,[1]גיליון1!$B:$G,6,FALSE) -> 0 | B3: Xiaomi 17 5G 12GB+512GB בצבע שחור | E3: =VLOOKUP(A3,[1]גיליון1!$A:$F,6,FALSE) -> #N/A | F3: [id=53806; name=Xiaomi 17 Black 1; url=/media/yg5gvams/xiaomi-17-black-1.jpg], [id=53807; name=Xiaomi 17 Black 2; url=/media/fjdojiyv/xiaomi-17-black-2.jpg], [id=53808; name=Xiaomi 17 Black 3; url=/media/nlqpthkz/xiaomi-17-black-3.jpg], [id=53809; name=Xiaomi 17 Black 4; url=/media/en0p4p2d/xiaomi-17-black-4.jpg]
A4: =VLOOKUP(B4,[1]גיליון1!$B:$G,6,FALSE) -> 0 | B4: Xiaomi 17 Ultra 5G 12GB+512GB בצבע שחור | E4: =VLOOKUP(A4,[1]גיליון1!$A:$F,6,FALSE) -> #N/A | F4: [id=53825; name=Xiaomi 17 Ultra Black 1; url=/media/ilvjiesy/xiaomi-17-ultra-black-1.jpg], [id=53826; name=Xiaomi 17 Ultra Black 2; url=/media/ntmjkzwn/xiaomi-17-ultra-black-2.jpg], [id=53827; name=Xiaomi 17 Ultra Black 3; url=/media/vkumexxu/xiaomi-17-ultra-black-3.jpg], [id=53828; name=Xiaomi 17 Ultra Black 4; url=/media/zivk4kou/xiaomi-17-ultra-black-4.jpg]
A5: =VLOOKUP(B5,[1]גיליון1!$B:$G,6,FALSE) -> 0 | B5: טאבלט Redmi Pad 2 Pro Wifi 8GB+256GB | E5: =VLOOKUP(A5,[1]גיליון1!$A:$F,6,FALSE) -> #N/A | F5: [id=53777; name=Redmi Pad 2 Pro WIFI Grey; url=/media/igxbp4zp/redmi_pad_2_pro___wifi_grey.jpg], [id=53778; name=Redmi Pad 2 Pro 0000 P83 WIFI Grey Back; url=/media/zvrbi1zw/redmi_pad_2_pro__0000_p83_wifi_grey-back.jpg], [id=53779; name=Redmi Pad 2 Pro 0001 P83 WIFI Grey Top; url=/media/40pfoflo/redmi_pad_2_pro__0001_p83_wifi_grey_top.jpg], [id=53780; name=Redmi Pad 2 Pro 0002 P83 WIFI Grey Right; url=/media/np3jjnih/redmi_pad_2_pro__0002_p83_wifi_grey_right.jpg], [id=53781; name=Redmi Pad 2 Pro 0003 P83 WIFI Grey Left; url=/media/eiqcyuyr/redmi_pad_2_pro__0003_p83_wifi_grey_left.jpg], [id=53782; name=Redmi Pad 2 Pro 0004 P83 WIFI Grey Frontright45; url=/media/vxfbnksz/redmi_pad_2_pro__0004_p83_wifi_grey_frontright45.jpg], [id=53783; name=Redmi Pad 2 Pro 0005 P83 WIFI Grey Frontleft45; url=/media/wi4n45s4/redmi_pad_2_pro__0005_p83_wifi_grey_frontleft45.jpg], [id=53784; name=Redmi Pad 2 Pro 0007 P83 WIFI Grey Front; url=/media/zp4putmm/redmi_pad_2_pro__0007_p83_wifi_grey_front.jpg], [id=53785; name=Redmi Pad 2 Pro 0008 P83 WIFI Grey Buttom; url=/media/rd1gh1ut/redmi_pad_2_pro__0008_p83_wifi_grey_buttom.jpg], [id=53786; name=Redmi Pad 2 Pro 0009 P83 WIFI Grey Backright45; url=/media/q4kdf3pu/redmi_pad_2_pro__0009_p83_wifi_grey_backright45.jpg], [id=53787; name=Redmi Pad 2 Pro 0010 P83 WIFI Grey Backleft45; url=/media/gp1ftqpa/redmi_pad_2_pro__0010_p83_wifi_grey_backleft45.jpg]
A6: =VLOOKUP(B6,[1]גיליון1!$B:$G,6,FALSE) -> 0 | B6: Xiaomi 17 5G 12GB+512GB בצבע כחול | E6: =VLOOKUP(A6,[1]גיליון1!$A:$F,6,FALSE) -> #N/A | F6: [id=53820; name=Xiaomi 17 Blue 1; url=/media/w3cpobcy/xiaomi-17-blue-1.jpg], [id=53821; name=Xiaomi 17 Blue 2; url=/media/zldn3v4y/xiaomi-17-blue-2.jpg], [id=53822; name=Xiaomi 17 Blue 3; url=/media/liinr31w/xiaomi-17-blue-3.jpg], [id=53823; name=Xiaomi 17 Blue 4; url=/media/ovbavmwx/xiaomi-17-blue-4.jpg]
A7: =VLOOKUP(B7,[1]גיליון1!$B:$G,6,FALSE) -> 0 | B7: Xiaomi 17 Ultra 5G 12GB+512GB בצבע לבן | E7: =VLOOKUP(A7,[1]גיליון1!$A:$F,6,FALSE) -> #N/A | F7: [id=53833; name=Xiaomi 17 Ultra White 1; url=/media/myinlnx3/xiaomi-17-ultra-white-1.jpg], [id=53834; name=Xiaomi 17 Ultra White 2; url=/media/1prpqc4r/xiaomi-17-ultra-white-2.jpg], [id=53835; name=Xiaomi 17 Ultra White 3; url=/media/bslpy2be/xiaomi-17-ultra-white-3.jpg], [id=53836; name=Xiaomi 17 Ultra White 4; url=/media/1ithne2z/xiaomi-17-ultra-white-4.jpg]
A8: =VLOOKUP(B8,[1]גיליון1!$B:$G,6,FALSE) -> 0 | B8: Samsung QLED Q7F 85" 4K Vision AI Smart TV 2025 | E8: =VLOOKUP(A8,[1]גיליון1!$A:$F,6,FALSE) -> #N/A | F8: [id=52227; name=1; url=/media/u0hf2gw4/1.png], [id=52228; name=2; url=/media/4kamsxkc/2.png], [id=52229; name=3; url=/media/adeplfi3/3.png], [id=52230; name=4; url=/media/ogfb12ac/4.png], [id=52175; name=7; url=/media/ojjamkts/7.png]
A9: =VLOOKUP(B9,[1]גיליון1!$B:$G,6,FALSE) -> 0 | B9: iPhone Air 256GB | E9: =VLOOKUP(A9,[1]גיליון1!$A:$F,6,FALSE) -> #N/A | F9: [id=50174; name=Iphone Air Space Black PDP Image Position 1 WWEN; url=/media/spoewd2v/iphone_air_space_black_pdp_image_position_1__wwen.jpg], [id=50175; name=Iphone Air Space Black PDP Image Position 2 WWEN; url=/media/vshpq50g/iphone_air_space_black_pdp_image_position_2__wwen.jpg], [id=50176; name=Iphone Air Space Black PDP Image Position 3 WWEN; url=/media/pofn2vxh/iphone_air_space_black_pdp_image_position_3__wwen.jpg], [id=50177; name=Iphone Air Space Black PDP Image Position 4 WWEN; url=/media/jpig1oe4/iphone_air_space_black_pdp_image_position_4__wwen.jpg], [id=50181; name=Iphone Air Sky Blue PDP Image Position 1 WWEN; url=/media/xe0p1ma0/iphone_air_sky_blue_pdp_image_position_1__wwen.jpg], [id=50182; name=Iphone Air Sky Blue PDP Image Position 2 WWEN; url=/media/imljf4en/iphone_air_sky_blue_pdp_image_position_2__wwen.jpg], [id=50183; name=Iphone Air Sky Blue PDP Image Position 3 WWEN; url=/media/bftd33em/iphone_air_sky_blue_pdp_image_position_3__wwen.jpg], [id=50184; name=Iphone Air Sky Blue PDP Image Position 4 WWEN; url=/media/arzmxj0s/iphone_air_sky_blue_pdp_image_position_4__wwen.jpg], [id=50185; name=Iphone Air Light Gold PDP Image Position 1 WWEN; url=/media/wl4osatd/iphone_air_light_gold_pdp_image_position_1__wwen.jpg], [id=50186; name=Iphone Air Light Gold PDP Image Position 2 WWEN; url=/media/eceje3yy/iphone_air_light_gold_pdp_image_position_2__wwen.jpg], [id=50187; name=Iphone Air Light Gold PDP Image Position 3 WWEN; url=/media/f43f5tva/iphone_air_light_gold_pdp_image_position_3__wwen.jpg], [id=50188; name=Iphone Air Light Gold PDP Image Position 4 WWEN; url=/media/gczljk13/iphone_air_light_gold_pdp_image_position_4__wwen.jpg], [id=50189; name=Iphone Air Cloud White PDP Image Position 1 WWEN; url=/media/l0nplvig/iphone_air_cloud_white_pdp_image_position_1__wwen.jpg], [id=50190; name=Iphone Air Cloud White PDP Image Position 2 WWEN; url=/media/wsgbdx2l/iphone_air_cloud_white_pdp_image_position_2__wwen.jpg], [id=50191; name=Iphone Air Cloud White PDP Image Position 3 WWEN; url=/media/aukkctw3/iphone_air_cloud_white_pdp_image_position_3__wwen.jpg], [id=50192; name=Iphone Air Cloud White PDP Image Position 4 WWEN; url=/media/qnmleh3d/iphone_air_cloud_white_pdp_image_position_4__wwen.jpg], [id=50178; name=Iphone Air Space Black PDP Image Position 5 WWEN; url=/media/z2opl51y/iphone_air_space_black_pdp_image_position_5__wwen.jpg], [id=50179; name=Iphone Air Space Black PDP Image Position 6 WWEN; url=/media/tqoivzar/iphone_air_space_black_pdp_image_position_6__wwen.jpg], [id=50180; name=Iphone Air Space Black PDP Image Position 7 WWEN; url=/media/k43hk5lf/iphone_air_space_black_pdp_image_position_7__wwen.jpg]
A10: =VLOOKUP(B10,[1]גיליון1!$B:$G,6,FALSE) -> 0 | B10: iPhone 17 Pro Max 1TB | E10: =VLOOKUP(A10,[1]גיליון1!$A:$F,6,FALSE) -> #N/A | F10: [id=50205; name=Iphone 17 Pro Silver PDP Image Position 1 WWEN; url=/media/w1wj4pgq/iphone_17_pro_silver_pdp_image_position_1__wwen.jpg], [id=50206; name=Iphone 17 Pro Silver PDP Image Position 2 WWEN; url=/media/5tzez00i/iphone_17_pro_silver_pdp_image_position_2__wwen.jpg], [id=50207; name=Iphone 17 Pro Silver PDP Image Position 3 WWEN; url=/media/04rfaeys/iphone_17_pro_silver_pdp_image_position_3__wwen.jpg], [id=50208; name=Iphone 17 Pro Silver PDP Image Position 4 WWEN; url=/media/0vfhnjix/iphone_17_pro_silver_pdp_image_position_4__wwen.jpg], [id=50194; name=Iphone 17 Pro Cosmic Orange PDP Image Position 1 WWEN; url=/media/zsdk3hed/iphone_17_pro_cosmic_orange_pdp_image_position_1__wwen.jpg], [id=50195; name=Iphone 17 Pro Cosmic Orange PDP Image Position 2 WWEN; url=/media/dfwht0vs/iphone_17_pro_cosmic_orange_pdp_image_position_2__wwen.jpg], [id=50196; name=Iphone 17 Pro Cosmic Orange PDP Image Position 3 WWEN; url=/media/gxplihix/iphone_17_pro_cosmic_orange_pdp_image_position_3__wwen.jpg], [id=50197; name=Iphone 17 Pro Cosmic Orange PDP Image Position 4 WWEN; url=/media/5v3lk01a/iphone_17_pro_cosmic_orange_pdp_image_position_4__wwen.jpg], [id=50201; name=Iphone 17 Pro Deep Blue PDP Image Position 1 WWEN; url=/media/x0dfamuy/iphone_17_pro_deep_blue_pdp_image_position_1__wwen.jpg], [id=50202; name=Iphone 17 Pro Deep Blue PDP Image Position 2 WWEN; url=/media/q3sha3so/iphone_17_pro_deep_blue_pdp_image_position_2__wwen.jpg], [id=50203; name=Iphone 17 Pro Deep Blue PDP Image Position 3 WWEN; url=/media/bjcf2j0g/iphone_17_pro_deep_blue_pdp_image_position_3__wwen.jpg], [id=50204; name=Iphone 17 Pro Deep Blue PDP Image Position 4 WWEN; url=/media/rsqddj4o/iphone_17_pro_deep_blue_pdp_image_position_4__wwen.jpg], [id=50198; name=Iphone 17 Pro Cosmic Orange PDP Image Position 5 WWEN; url=/media/dziajhsy/iphone_17_pro_cosmic_orange_pdp_image_position_5__wwen.jpg], [id=50199; name=Iphone 17 Pro Cosmic Orange PDP Image Position 6 WWEN; url=/media/h3udrhet/iphone_17_pro_cosmic_orange_pdp_image_position_6__wwen.jpg], [id=50200; name=Iphone 17 Pro Cosmic Orange PDP Image Position 7 WWEN; url=/media/soopyioi/iphone_17_pro_cosmic_orange_pdp_image_position_7__wwen.jpg]
A11: =VLOOKUP(B11,[1]גיליון1!$B:$G,6,FALSE) -> 0 | B11: iPhone 17 Pro Max 2TB | E11: =VLOOKUP(A11,[1]גיליון1!$A:$F,6,FALSE) -> #N/A | F11: [id=50194; name=Iphone 17 Pro Cosmic Orange PDP Image Position 1 WWEN; url=/media/zsdk3hed/iphone_17_pro_cosmic_orange_pdp_image_position_1__wwen.jpg], [id=50195; name=Iphone 17 Pro Cosmic Orange PDP Image Position 2 WWEN; url=/media/dfwht0vs/iphone_17_pro_cosmic_orange_pdp_image_position_2__wwen.jpg], [id=50196; name=Iphone 17 Pro Cosmic Orange PDP Image Position 3 WWEN; url=/media/gxplihix/iphone_17_pro_cosmic_orange_pdp_image_position_3__wwen.jpg], [id=50197; name=Iphone 17 Pro Cosmic Orange PDP Image Position 4 WWEN; url=/media/5v3lk01a/iphone_17_pro_cosmic_orange_pdp_image_position_4__wwen.jpg], [id=50201; name=Iphone 17 Pro Deep Blue PDP Image Position 1 WWEN; url=/media/x0dfamuy/iphone_17_pro_deep_blue_pdp_image_position_1__wwen.jpg], [id=50202; name=Iphone 17 Pro Deep Blue PDP Image Position 2 WWEN; url=/media/q3sha3so/iphone_17_pro_deep_blue_pdp_image_position_2__wwen.jpg], [id=50203; name=Iphone 17 Pro Deep Blue PDP Image Position 3 WWEN; url=/media/bjcf2j0g/iphone_17_pro_deep_blue_pdp_image_position_3__wwen.jpg], [id=50204; name=Iphone 17 Pro Deep Blue PDP Image Position 4 WWEN; url=/media/rsqddj4o/iphone_17_pro_deep_blue_pdp_image_position_4__wwen.jpg], [id=50205; name=Iphone 17 Pro Silver PDP Image Position 1 WWEN; url=/media/w1wj4pgq/iphone_17_pro_silver_pdp_image_position_1__wwen.jpg], [id=50206; name=Iphone 17 Pro Silver PDP Image Position 2 WWEN; url=/media/5tzez00i/iphone_17_pro_silver_pdp_image_position_2__wwen.jpg], [id=50207; name=Iphone 17 Pro Silver PDP Image Position 3 WWEN; url=/media/04rfaeys/iphone_17_pro_silver_pdp_image_position_3__wwen.jpg], [id=50208; name=Iphone 17 Pro Silver PDP Image Position 4 WWEN; url=/media/0vfhnjix/iphone_17_pro_silver_pdp_image_position_4__wwen.jpg], [id=50199; name=Iphone 17 Pro Cosmic Orange PDP Image Position 6 WWEN; url=/media/h3udrhet/iphone_17_pro_cosmic_orange_pdp_image_position_6__wwen.jpg], [id=50198; name=Iphone 17 Pro Cosmic Orange PDP Image Position 5 WWEN; url=/media/dziajhsy/iphone_17_pro_cosmic_orange_pdp_image_position_5__wwen.jpg], [id=50200; name=Iphone 17 Pro Cosmic Orange PDP Image Position 7 WWEN; url=/media/soopyioi/iphone_17_pro_cosmic_orange_pdp_image_position_7__wwen.jpg]
A12: =VLOOKUP(B12,[1]גיליון1!$B:$G,6,FALSE) -> 0 | B12: מסך מחשב - Xiaomi Gaming Monitor G27i IPS 165Hz 27" | E12: =VLOOKUP(A12,[1]גיליון1!$A:$F,6,FALSE) -> #N/A | F12: [id=39841; name=Xiaomi Gaming Monitor G27i 4; url=/media/pebgcuhn/xiaomi-gaming-monitor-g27i_4.jpg], [id=39839; name=Xiaomi Gaming Monitor G27i 2; url=/media/nztfhucm/xiaomi-gaming-monitor-g27i_2.jpg], [id=39840; name=Xiaomi Gaming Monitor G27i 3; url=/media/ncqp0zb3/xiaomi-gaming-monitor-g27i_3.jpg], [id=39842; name=Xiaomi Gaming Monitor G27i 5; url=/media/1y4foqxe/xiaomi-gaming-monitor-g27i_5.jpg], [id=39843; name=Xiaomi Gaming Monitor G27i 6; url=/media/ibugmtbl/xiaomi-gaming-monitor-g27i_6.jpg], [id=39844; name=Xiaomi Gaming Monitor G27i 8; url=/media/f42dkkff/xiaomi-gaming-monitor-g27i_8.jpg]
A13: =VLOOKUP(B13,[1]גיליון1!$B:$G,6,FALSE) -> 0 | B13: מסך מחשב - Xiaomi 2K Gaming Monitor G27Qi IPS 180Hz | E13: =VLOOKUP(A13,[1]גיליון1!$A:$F,6,FALSE) -> #N/A | F13: [id=41329; name=Xiaomi 2K Gaming Monitor G27qi EU 1; url=/media/ndkpsxt1/xiaomi-2k-gaming-monitor-g27qi-eu_1.jpg], [id=41330; name=Xiaomi 2K Gaming Monitor G27qi EU 2; url=/media/lhhpiltx/xiaomi-2k-gaming-monitor-g27qi-eu_2.jpg], [id=41331; name=Xiaomi 2K Gaming Monitor G27qi EU 3; url=/media/2ooecqfn/xiaomi-2k-gaming-monitor-g27qi-eu_3.jpg], [id=41332; name=Xiaomi 2K Gaming Monitor G27qi EU 4; url=/media/qizdfcnd/xiaomi-2k-gaming-monitor-g27qi-eu_4.jpg]
... A248: =VLOOKUP(B248,[1]גיליון1!$B:$G,6,FALSE) -> 0 | B248: כיסוי לנייד Galaxy A15 Otterbox React - שחור | E248: =VLOOKUP(A248,[1]גיליון1!$A:$F,6,FALSE) -> #N/A | F248: [id=35728; name=Illenium React Black Pkg; url=/media/fl3bymzb/illenium-react-black-pkg.jpg], [id=35730; name=Palewaves React Black D B; url=/media/jmlnpie5/palewaves-react-black-d-b.jpg], [id=35731; name=Palewaves React Black D Br; url=/media/luzbiaep/palewaves-react-black-d-br.jpg], [id=35732; name=Palewaves React Black D Falling; url=/media/2uvhjfue/palewaves-react-black-d-falling.jpg], [id=35733; name=Palewaves React Black D Split; url=/media/tfudiyks/palewaves-react-black-d-split.jpg]
